ERROR: Remote error: CircularDependencyException Circular Dependency Found: {CinderVolumeAttachment "cinder_volume": {CinderVolumeAttachment "cinder_volume"}}
[u'Traceback (most recent call last):\n', u'  File "/opt/stack/heat/heat/engine/service.py", line 72, in wrapped\n    return func(self, ctx, *args, **kwargs)\n', u'  File "/opt/stack/heat/heat/engine/service.py", line 621, in preview_stack\n    args)\n', u'  File "/opt/stack/heat/heat/engine/service.py", line 596, in _parse_template_and_validate_stack\n    stack.validate()\n', u'  File "/usr/lib/python2.7/site-packages/osprofiler/profiler.py", line 105, in wrapper\n    return f(*args, **kwargs)\n', u'  File "/opt/stack/heat/heat/engine/stack.py", line 471, in validate\n    for res in self.dependencies:\n', u'  File "/opt/stack/heat/heat/engine/dependencies.py", line 173, in toposort\n    raise CircularDependencyException(cycle=six.text_type(graph))\n', u'CircularDependencyException: Circular Dependency Found: {CinderVolumeAttachment "cinder_volume": {CinderVolumeAttachment "cinder_volume"}}\n'].

2014-11-25 17:07:59.114 ERROR root [req-57ade939-7076-4d0c-b531-cf1f3a00cafc admin demo] Unexpected error occurred serving API: Remote error: Remote error: CircularDependencyException Circular Dependency Found: 
{CinderVolumeAttachment "cinder_volume": {CinderVolumeAttachment "cinder_volume"}}
[u'Traceback (most recent call last):\n', u'  File "/opt/stack/heat/heat/engine/service.py", line 72, in wrapped\n    return func(self, ctx, *args, **kwargs)\n', u'  File "/opt/stack/heat/heat/engine/service.py"
, line 621, in preview_stack\n    args)\n', u'  File "/opt/stack/heat/heat/engine/service.py", line 596, in _parse_template_and_validate_stack\n    stack.validate()\n', u'  File "/usr/lib/python2.7/site-packages
/osprofiler/profiler.py", line 105, in wrapper\n    return f(*args, **kwargs)\n', u'  File "/opt/stack/heat/heat/engine/stack.py", line 471, in validate\n    for res in self.dependencies:\n', u'  File "/opt/stac
k/heat/heat/engine/dependencies.py", line 173, in toposort\n    raise CircularDependencyException(cycle=six.text_type(graph))\n', u'CircularDependencyException: Circular Dependency Found: {CinderVolumeAttachment
 "cinder_volume": {CinderVolumeAttachment "cinder_volume"}}\n']. None
None.
2014-11-25 17:07:59.114 TRACE root Traceback (most recent call last):
2014-11-25 17:07:59.114 TRACE root   File "/opt/stack/heat/heat/common/wsgi.py", line 634, in __call__
2014-11-25 17:07:59.114 TRACE root     request, **action_args)
2014-11-25 17:07:59.114 TRACE root   File "/opt/stack/heat/heat/common/wsgi.py", line 708, in dispatch
2014-11-25 17:07:59.114 TRACE root     return method(*args, **kwargs)
2014-11-25 17:07:59.114 TRACE root   File "/opt/stack/heat/heat/api/openstack/v1/util.py", line 40, in handle_stack_method
2014-11-25 17:07:59.114 TRACE root     return handler(controller, req, **kwargs)
2014-11-25 17:07:59.114 TRACE root   File "/opt/stack/heat/heat/api/openstack/v1/stacks.py", line 269, in preview
2014-11-25 17:07:59.114 TRACE root     data.args())
2014-11-25 17:07:59.114 TRACE root   File "/opt/stack/heat/heat/rpc/client.py", line 162, in preview_stack
2014-11-25 17:07:59.114 TRACE root     params=params, files=files, args=args))
2014-11-25 17:07:59.114 TRACE root   File "/opt/stack/heat/heat/rpc/client.py", line 50, in call
2014-11-25 17:07:59.114 TRACE root     return client.call(ctxt, method, **kwargs)
2014-11-25 17:07:59.114 TRACE root   File "/usr/lib/python2.7/site-packages/oslo/messaging/rpc/client.py", line 389, in call
2014-11-25 17:07:59.114 TRACE root     return self.prepare().call(ctxt, method, **kwargs)
2014-11-25 17:07:59.114 TRACE root   File "/usr/lib/python2.7/site-packages/oslo/messaging/rpc/client.py", line 152, in call
2014-11-25 17:07:59.114 TRACE root     retry=self.retry)
2014-11-25 17:07:59.114 TRACE root   File "/usr/lib/python2.7/site-packages/oslo/messaging/transport.py", line 90, in _send
2014-11-25 17:07:59.114 TRACE root     timeout=timeout, retry=retry)
2014-11-25 17:07:59.114 TRACE root   File "/usr/lib/python2.7/site-packages/oslo/messaging/_drivers/amqpdriver.py", line 408, in send
2014-11-25 17:07:59.114 TRACE root     retry=retry)
2014-11-25 17:07:59.114 TRACE root   File "/usr/lib/python2.7/site-packages/oslo/messaging/_drivers/amqpdriver.py", line 399, in _send
2014-11-25 17:07:59.114 TRACE root     raise result
2014-11-25 17:07:59.114 TRACE root RemoteError: Remote error: CircularDependencyException Circular Dependency Found: {CinderVolumeAttachment "cinder_volume": {CinderVolumeAttachment "cinder_volume"}}
2014-11-25 17:07:59.114 TRACE root [u'Traceback (most recent call last):\n', u'  File "/opt/stack/heat/heat/engine/service.py", line 72, in wrapped\n    return func(self, ctx, *args, **kwargs)\n', u'  File "/opt/stack/heat/heat/engine/service.py", line 621, in preview_stack\n    args)\n', u'  File "/opt/stack/heat/heat/engine/service.py", line 596, in _parse_template_and_validate_stack\n    stack.validate()\n', u'  File "/usr/lib/python2.7/site-packages/osprofiler/profiler.py", line 105, in wrapper\n    return f(*args, **kwargs)\n', u'  File "/opt/stack/heat/heat/engine/stack.py", line 471, in validate\n    for res in self.dependencies:\n', u'  File "/opt/stack/heat/heat/engine/dependencies.py", line 173, in toposort\n    raise CircularDependencyException(cycle=six.text_type(graph))\n', u'CircularDependencyException: Circular Dependency Found: {CinderVolumeAttachment "cinder_volume": {CinderVolumeAttachment "cinder_volume"}}\n'].
2014-11-25 17:07:59.114 TRACE root 
